<?xml version="1.0"?>
<robot name="rc_car" xmlns:xacro="http://ros.org/wiki/xacro">
	  <!-- Define robot constants -->
  <xacro:property name="base_width" value="0.18"/>
  <xacro:property name="base_length" value="0.33"/>
  <xacro:property name="base_height" value="0.08"/>

  <xacro:property name="wheel_back_radius" value="0.06"/>
  <xacro:property name="wheel_back_width" value="0.05"/>
  <xacro:property name="wheel_back_ygap" value="0.01"/>
  <xacro:property name="wheel_back_zoff" value="-0.06"/>
  <xacro:property name="wheel_back_xoff" value="-0.2"/>

  <xacro:property name="wheel_front_radius" value="0.06"/>
  <xacro:property name="wheel_front_width" value="0.05"/>
  <xacro:property name="wheel_front_ygap" value="0.01"/>
  <xacro:property name="wheel_front_zoff" value="-0.06"/>
  <xacro:property name="wheel_front_xoff" value="0.15"/>
  <xacro:property name="caster_xoff" value="0.14"/>

  
    <!-- Robot Base -->
  <link name="base_link">
    <visual>
      <geometry>
        <box size="${base_length} ${base_width} ${base_height}"/>
      </geometry>
      <material name="Cyan">
        <color rgba="0 1.0 1.0 1.0"/>
      </material>
    </visual>
  </link>

    <!-- Robot Footprint -->
  <link name="base_footprint"/>

  <joint name="base_link" type="fixed">
    <parent link="base_link"/>
    <child link="base_footprint"/>
    <origin xyz="0.0 0.0 -0.12" rpy="0 0 0"/>
  </joint>


  <!-- Stereo Camera -->
  <link name="oak-d_frame">
    <visual>
      <geometry>
        <box size="0.03 0.06 0.04"/>
      </geometry>
      <material name="Cyan">
        <color rgba="0 1.0 1.0 1.0"/>
      </material>
    </visual>
  </link>

  <joint name="stereo_cam_joint" type="fixed">
    <parent link="base_link"/>
    <child link="oak-d_frame"/>
    <origin xyz="0.26 0.0 0.03" rpy="0 0 0"/>
  </joint>

  <link name="oak-d-base-frame">
    <visual>
      <geometry>
        <box size="0.03 0.06 0.04"/>
      </geometry>
      <material name="Cyan">
        <color rgba="0 1.0 1.0 1.0"/>
      </material>
    </visual>
  </link>

  <joint name="oak-d-base-frame" type="fixed">
    <parent link="base_link"/>
    <child link="oak-d-base-frame"/>
    <origin xyz="0.26 0.0 0.03" rpy="0 0 0"/>
  </joint>


    <!-- Wheels -->
  <xacro:macro name="wheel" params="prefix x_reflect y_reflect">
    <link name="${prefix}_link">
      <visual>
        <origin xyz="0 0 0" rpy="${pi/2} 0 0"/>
        <geometry>
            <cylinder radius="${wheel_back_radius}" length="${wheel_back_width}"/>
        </geometry>
        <material name="Gray">
          <color rgba="0.5 0.5 0.5 1.0"/>
        </material>
      </visual>
    </link>

    <joint name="${prefix}_joint" type="continuous">
      <parent link="oak-d_frame"/>
      <child link="${prefix}_link"/>
      <origin xyz="${-x_reflect*wheel_back_xoff - 0.26} ${y_reflect*(base_width/2+wheel_back_ygap)} -0.1" rpy="0 0 0"/>
      <axis xyz="0 1 0"/>
    </joint>
  </xacro:macro>

  <xacro:wheel prefix="drivewhl_bl" x_reflect="-1" y_reflect="1" />
  <xacro:wheel prefix="drivewhl_br" x_reflect="-1" y_reflect="-1" />
  <xacro:wheel prefix="drivewhl_fl" x_reflect="1" y_reflect="-1" />
  <xacro:wheel prefix="drivewhl_fr" x_reflect="1" y_reflect="1" />

  

  
  <!-- GPS unit -->
  <link name="gps_unit">
    <visual>
      <geometry>
        <box size="0.06 0.06 0.02"/>
      </geometry>
      <material name="Cyan">
        <color rgba="0 1.0 1.0 1.0"/>
      </material>
    </visual>
  </link>

  <joint name="gps_unit_joint" type="fixed">
    <parent link="base_link"/>
    <child link="gps_unit"/>
    <origin xyz="-0.26 0.0 0.03" rpy="0 0 0"/>
  </joint>


  <!-- IMU board -->
  <link name="imu_board">
    <visual>
      <geometry>
        <box size="0.02 0.08 0.08"/>
      </geometry>
      <material name="Cyan">
        <color rgba="0 1.0 1.0 1.0"/>
      </material>
    </visual>
  </link>

  <joint name="imu_board_joint" type="fixed">
    <parent link="base_link"/>
    <child link="imu_board"/>
    <origin xyz="-0.08 0.0 0.08" rpy="0 0 0"/>
  </joint>



</robot>
